<?xml version="1.0"?>

<robot name="agv" xmlns:xacro="http://www.ros.org/wiki/xacro">

  <xacro:property name="laser_visual" value="true"/>
  <xacro:property name="imu_visual" value="false"/>


  <xacro:property name="PI" value="3.1415926535897931"/>

  <xacro:property name="chassisHeight" value="1"/>
  <xacro:property name="chassisLength" value="0.84"/>
  <xacro:property name="chassisWidth" value="0.7"/>
  <xacro:property name="chassisMass" value="100"/>

  <xacro:property name="casterRadius" value="0.125"/>
  <xacro:property name="casterWidth" value="0.05"/>
  <xacro:property name="casterMass" value="2"/>

  <xacro:property name="wheelWidth" value="0.08"/>
  <xacro:property name="wheelRadius" value="0.125"/>
  <xacro:property name="wheelMass" value="3"/>

  <xacro:property name="supportWheelWidth" value="0.07"/>
  <xacro:property name="supportWheelRadius" value="0.082"/>
  <xacro:property name="supportWheelMass" value="1"/>

  <xacro:property name="cameraSize" value="0.06"/>
  <xacro:property name="cameraMass" value="0.5"/>

  <xacro:include filename="$(find agv_description)/urdf/agv.gazebo" />
  <xacro:include filename="$(find agv_description)/urdf/materials.xacro" />
  <xacro:include filename="$(find agv_description)/urdf/macros.xacro" />

  <link name="footprint" />

  <joint name="base_joint" type="fixed">
    <parent link="footprint"/>
    <child link="chassis"/>
  </joint>

  <link name="chassis">
    <collision>
      <origin xyz="0 0 0.625" rpy="0 0 0"/>
      <geometry>
	<box size="${chassisLength} ${chassisWidth} ${chassisHeight}"/>
      </geometry>
    </collision>

    <visual>
      <origin xyz="0 0 0.625" rpy="0 0 0"/>
      <geometry>
	<box size="${chassisLength} ${chassisWidth} ${chassisHeight}"/>
      </geometry>
      <material name="yellow"/>
    </visual>

    <inertial>
      <origin xyz="0 0 0.625" rpy="0 0 0"/>
      <mass value="${chassisMass}"/>
      <box_inertia m="${chassisMass}" x="${chassisLength}" y="${chassisWidth}" z="${chassisHeight}"/>
    </inertial>
  </link>

  <joint name="imu_joint" type="fixed">
    <parent link="chassis"/>
    <child link="imu_link"/>
    <origin xyz="0 0.2 0.5" rpy="0 0 0"/>
  </joint>

  <link name="imu_link"/>


    <joint name="base_steer_joint" type="revolute">
        <parent link="chassis"/>
        <child link="steer_link"/>
        <origin xyz="0 0.2 1.125"/>
        <limit effort="1" velocity="0.25" lower="-1.20" upper="1.20"/>
        <axis xyz="0 0 1"/>
    </joint>

    <transmission name="trans1">
      <type>transmission_interface/SimpleTransmission</type>
      <joint name="base_steer_joint">
         <hardwareInterface>EffortJointInterface</hardwareInterface>
      </joint>
      <actuator name="motor1">
          <hardwareInterface>EffortJointInterface</hardwareInterface>
          <mechanicalReduction>1</mechanicalReduction>
      </actuator>

   </transmission>

    <link name="steer_link">
        <visual>
            <origin xyz="0 0 0.195" rpy="0 0 0"/>
            <geometry>
                <cylinder length="0.39" radius="0.1"/>
            </geometry>
            <material name="black"/>
        </visual>
        <inertial>
            <origin xyz="0 0 0.195" rpy="0 0 0"/>
            <mass value="1.5"/>
            <cylinder_inertia m="1.5" r="0.1" h="0.39"/>
        </inertial>
    </link>

    <joint name="steer_to_roll_joint" type="continuous">
        <parent link="steer_link"/>
        <child link="roll_link"/>
        <origin xyz="0 0 -1" rpy="0 0 0"/>
        <limit effort="0.1" velocity="0.35"/>
        <axis xyz="1 0 0"/>
    </joint>

    <transmission name="trans2">
      <type>transmission_interface/SimpleTransmission</type>
      <joint name="steer_to_roll_joint">
         <hardwareInterface>EffortJointInterface</hardwareInterface>
      </joint>
      <actuator name="motor2">
          <hardwareInterface>EffortJointInterface</hardwareInterface>
          <mechanicalReduction>1</mechanicalReduction>
      </actuator>

   </transmission>


    <link name="roll_link">
        <visual>
            <origin xyz="0 0 0" rpy="0 1.57 0"/>
            <geometry>
                <cylinder length="${wheelWidth}" radius="${wheelRadius}"/>
            </geometry>
            <material name="orange"/>
        </visual>
        <inertial>
            <origin xyz="0 0 0" rpy="0 1.57 0"/>
            <mass value="${wheelMass}"/>
            <cylinder_inertia m="${wheelMass}" r="${wheelRadius}" h="${wheelWidth}"/>
        </inertial>
    </link>

  <caster_wheel lr="left" tY="-0.285"/>
  <caster_wheel lr="right" tY="0.285"/>


    <joint name="forklift_base_joint" type="fixed">
        <parent link="chassis"/>
        <child link="forklift_base"/>
        <origin rpy="0 0 0" xyz="0 -0.395 0.043"/>
    </joint>

    <link name="forklift_base">
        <visual>
            <origin xyz="0 0 1" rpy="0 0 0"/>
            <geometry>
                <box size="0.84 0.09 2"/>
            </geometry>
            <material name="black"/>
        </visual>
        <collision>
            <origin xyz="0 0 1" rpy="0 0 0"/>
            <geometry>
                <box size="0.84 0.09 2"/>
            </geometry>
            <material name="black"/>

        </collision>
        <inertial>
            <origin xyz="0 0 1" rpy="0 0 0"/>
            <mass value="50"/>
            <box_inertia m="50" x="0.84" y="0.09" z="2"/>
        </inertial>
    </link>

    <joint name="laser_joint" type="fixed">
        <parent link="forklift_base"/>
        <child link="laser_link"/>
        <origin rpy="0 0 0" xyz="0 0 2.025"/>
    </joint>

    <link name="laser_link">
        <visual>
            <origin xyz="0 0 0" rpy="0 0 0"/>
            <geometry>
                <box size="${cameraSize} ${cameraSize} ${cameraSize}"/>
            </geometry>
            <material name="red"/>
        </visual>
        <inertial>
            <origin xyz="0 0 0" rpy="0 0 0"/>
            <mass value="${cameraMass}"/>
            <box_inertia m="${cameraMass}" x="${cameraSize}" y="${cameraSize}" z="${cameraSize}"/>
        </inertial>
        <collision>
            <origin xyz="0 0 0" rpy="0 0 0"/>
            <geometry>
                <box size="${cameraSize} ${cameraSize} ${cameraSize}"/>
            </geometry>
        </collision>

    </link>


    <joint name="forklift_prismatic_joint" type="prismatic">
        <parent link="forklift_base"/>
        <child link="forklift_prismatic_link"/>
        <origin rpy="0 0 0" xyz="0 -0.045 0"/>
        <limit effort="10" velocity="1.0" lower="0.0" upper="1.5"/>
        <axis xyz="0 0 1"/>
        <calibration rising="-0.5"/>
         
    </joint>


    <transmission name="trans3">
      <type>transmission_interface/SimpleTransmission</type>
      <joint name="forklift_prismatic_joint">
         <hardwareInterface>EffortJointInterface</hardwareInterface>
      </joint>
      <actuator name="motor3">
          <hardwareInterface>EffortJointInterface</hardwareInterface>
          <mechanicalReduction>1</mechanicalReduction>
      </actuator>

   </transmission>



    <link name="forklift_prismatic_link">
        <visual>
            <origin xyz="0 0 0" rpy="0 0 0"/>
            <geometry>
                <box size="0.84 0.05 0.06"/>
            </geometry>
            <material name="yellow"/>
        </visual>
        <collision>
            <origin xyz="0 0 0" rpy="0 0 0"/>
            <geometry>
                <box size="0.84 0.05 0.06"/>
            </geometry>
        </collision>
        <inertial>
            <origin xyz="0 0 0" rpy="0 0 0"/>
            <mass value="3"/>
            <box_inertia m="3" x="0.84" y="0.05" z="0.06"/>

        </inertial>
    </link>

  <forklift lr="left" tY="-0.280"/>
  <forklift lr="right" tY="0.280"/>

  <camera lr="left" tY="-0.055"/>
  <camera lr="right" tY="0.055"/>









  


 
</robot>
