<?xml version="1.0"?>
<robot>
     <macro name="cylinder_inertia" params="m r h">
        <inertia  ixx="${m*(3*r*r+h*h)/12}" ixy = "0" ixz = "0"
                  iyy="${m*(3*r*r+h*h)/12}" iyz = "0"
                  izz="${m*r*r/2}" /> 
      </macro>

      <macro name="box_inertia" params="m x y z">
        <inertia  ixx="${m*(y*y+z*z)/12}" ixy = "0" ixz = "0"
                  iyy="${m*(x*x+z*z)/12}" iyz = "0"
                  izz="${m*(x*x+z*z)/12}" /> 
      </macro>

      <macro name="sphere_inertia" params="m r">
        <inertia  ixx="${2*m*r*r/5}" ixy = "0" ixz = "0"
                  iyy="${2*m*r*r/5}" iyz = "0"
                  izz="${2*m*r*r/5}" /> 
      </macro>

    <macro name="caster_wheel" params="lr tY">

      <joint name="${lr}_caster_yawn_joint" type="revolute">
        <parent link="chassis"/>
        <child link="${lr}_caster_base_link"/>
        <origin rpy="0 0 0" xyz="${tY} 0.2 0.125"/>
        <limit effort="0.01" velocity="0.4" lower="-1.5" upper="1.5" />
        <axis xyz="0 0 1"/>
      </joint>


      <link name="${lr}_caster_base_link">
        <visual>
            <origin xyz="0 0 0" rpy="0 0 0"/>
            <geometry>
                <cylinder length="0.005" radius="0.005"/>
            </geometry>
        </visual>
        <inertial>
            <origin xyz="0 0 0" rpy="0 0 0"/>
            <mass value="0.005"/>
            <cylinder_inertia m="0.005" r="0.005" h="0.005"/>
        </inertial>

      </link>

       <joint name="${lr}_wheel_hinge" type="continuous">
          <parent link="${lr}_caster_base_link"/>
          <child link="${lr}_wheel"/>
          <origin xyz="0 0 0" rpy="0 0 0" /> 
          <axis xyz="1 0 0"/>
          <limit effort="1" velocity="0.01"/>
       </joint>


       <link name="${lr}_wheel">
        <!--collision>
          <origin xyz="0 0 0" rpy="0 ${PI/2} 0" />
          <geometry>
           <cylinder length="${casterWidth}" radius="${casterRadius}"/>
          </geometry>
        </collision-->

        <visual>
          <origin xyz="0 0 0" rpy="0 ${PI/2} 0" />
          <geometry>
           <cylinder length="${casterWidth}" radius="${casterRadius}"/>
          </geometry>
          <material name="orange"/>
        </visual>

        <inertial>
          <origin xyz="0 0 0" rpy="0 ${PI/2} 0" />
          <mass value="${casterMass}"/>
          <cylinder_inertia m="${casterMass}" r="${casterRadius}" h="${casterWidth}"/>
        </inertial>
       </link>

        <gazebo reference="${lr}_wheel">
          <mu1 value="1.0"/>
          <mu2 value="1.0"/>
          <kp  value="10000000.0" />
          <kd  value="10000000.0" />
          <fdir1 value="1 0 0"/>
          <material>Gazebo/Orange</material>
        </gazebo>

    </macro>

    <macro name="forklift" params="lr tY">
     <joint name="${lr}_foklift_support_joint" type="fixed">
        <parent link="forklift_prismatic_link"/>
        <child link="${lr}_forklift_moving_link"/>
        <origin xyz="${tY} -0.025 0" rpy="0 0 0"/>
      </joint>

    <link name="${lr}_forklift_moving_link">
        <visual>
            <origin xyz="0 -0.55 0" rpy="0 0 0"/>
            <geometry>
                <box size="0.285 1.1 0.06"/>
            </geometry>
            <material name="yellow"/>
        </visual>
        <collision>
            <origin xyz="0 -0.55 0" rpy="0 0 0"/>
            <geometry>
                <box size="0.285 1.1 0.06"/>
            </geometry>
        </collision>
        <inertial>
            <origin xyz="0 -0.55 0" rpy="0 0 0"/>
            <mass value="50"/>
            <box_inertia m="50" x="0.285" y="1.1" z="0.06"/>
        </inertial>
    </link>

    <joint name="${lr}_bogie_load_joint1" type="continuous">
        <parent link="${lr}_forklift_moving_link"/>
        <child link="${lr}_bogie_load_wheel1"/>
        <origin rpy="0 0 0" xyz="0 -0.851 0"/>
        <limit effort="0.01" velocity="0.01"/>
        <axis xyz="1 0 0"/>
    </joint>


    <gazebo reference="${lr}_forklift_moving_link">
        <material>Gazebo/Yellow</material>
    </gazebo>


    <link name="${lr}_bogie_load_wheel1">
        <visual>
            <origin xyz="0 0 0" rpy="0 1.57 0"/>
            <geometry>
                <cylinder length="${supportWheelWidth}" radius="${supportWheelRadius}"/>
            </geometry>
            <material name="blue"/>
        </visual>
        <inertial>
            <origin xyz="0 0 0" rpy="0 1.57 0"/>
            <mass value="${supportWheelMass}"/>
            <cylinder_inertia m="${supportWheelMass}" r="${supportWheelRadius}" h="${supportWheelWidth}"/>
        </inertial>
    </link>

    <gazebo reference="${lr}_bogie_load_wheel1">
            <mu1>1</mu1>
	    <mu2>1</mu2>
	    <kp>5000000.0</kp>
	    <kd>1000000.0</kd>
	    <maxVel>0.1</maxVel>
	    <fdir1>1 0 0</fdir1>
	    <material>Gazebo/Blue</material>
    </gazebo>




    <joint name="${lr}_bogie_load_joint2" type="continuous">
        <parent link="${lr}_forklift_moving_link"/>
        <child link="${lr}_bogie_load_wheel2"/>
        <origin rpy="0 0 0" xyz="0 -0.769 0"/>
        <limit effort="0.01" velocity="0.01"/>
        <axis xyz="1 0 0"/>
    </joint>

    <link name="${lr}_bogie_load_wheel2">
        <visual>
            <origin xyz="0 0 0" rpy="0 1.57 0"/>
            <geometry>
                <cylinder length="${supportWheelWidth}" radius="${supportWheelRadius}"/>
            </geometry>
            <material name="blue"/>
        </visual>
        <inertial>
            <origin xyz="0 0 0" rpy="0 1.57 0"/>
            <mass value="${supportWheelMass}"/>
            <cylinder_inertia m="${supportWheelMass}" r="${supportWheelRadius}" h="${supportWheelWidth}"/>
        </inertial>
    </link>

    <gazebo reference="${lr}_bogie_load_wheel2">
	    <mu1>1</mu1>
	    <mu2>1</mu2>
	    <kp>5000000.0</kp>
	    <kd>1000000.0</kd>
	    <maxVel>0.1</maxVel>
	    <fdir1>1 0 0</fdir1>
	    <material>Gazebo/Blue</material>
    </gazebo>
      
  </macro>

  <macro name="camera" params="lr tY">
    <joint name="${lr}_camera_joint" type="fixed">
        <parent link="forklift_base"/>
        <child link="${lr}_camera_link"/>
        <origin rpy="0 0 0" xyz="0 ${tY} 1.75"/>
    </joint>

    <link name="${lr}_camera_link">
        <visual>
            <origin xyz="0 0 0" rpy="0 0 0"/>
            <geometry>
                <box size="${cameraSize} ${cameraSize} ${cameraSize}"/>
            </geometry>
            <material name="green"/>
        </visual>
        <inertial>
            <origin xyz="0 0 0" rpy="0 0 0"/>
            <mass value="${cameraMass}"/>
            <box_inertia m="${cameraMass}" x="${cameraSize}" y="${cameraSize}" z="${cameraSize}"/>
        </inertial>
    </link>
    <gazebo reference="${lr}_camera_link">
      <material>Gazebo/Blue</material>
    </gazebo>


  </macro>
</robot>
